Sat May  5 23:04:47 2018 selector starting...
Traceback (most recent call last):
  File "selector.py", line 68, in <module>
    linkdb_logic = linkdbLogic.linkdbLogic(config['mysql_config'])
  File "/home/mfl/code/crawler/dbacessor/linkdbLogic.py", line 27, in __init__
    passwd = mysql_config['password'])
  File "/home/mfl/pyenv/env2/local/lib/python2.7/site-packages/MySQLdb/__init__.py", line 81, in Connect
    return Connection(*args, **kwargs)
  File "/home/mfl/pyenv/env2/local/lib/python2.7/site-packages/MySQLdb/connections.py", line 193, in __init__
    super(Connection, self).__init__(*args, **kwargs2)
_mysql_exceptions.OperationalError: (2003, "Can't connect to MySQL server on '127.0.0.1' (111)")
Sat May  5 23:38:41 2018 selector starting...
Traceback (most recent call last):
  File "selector.py", line 93, in <module>
    url_list = linkdb_logic.select_url_by_host(host_info[host], host_min_urlno.get(host, 0), limit = 400)
  File "/home/mfl/code/crawler/dbacessor/linkdbLogic.py", line 264, in select_url_by_host
    count = cursor.execute(strSQL)
  File "/home/mfl/pyenv/env2/local/lib/python2.7/site-packages/MySQLdb/cursors.py", line 205, in execute
    self.errorhandler(self, exc, value)
  File "/home/mfl/pyenv/env2/local/lib/python2.7/site-packages/MySQLdb/connections.py", line 36, in defaulterrorhandler
    raise errorclass, errorvalue
_mysql_exceptions.OperationalError: (2013, 'Lost connection to MySQL server during query')
Sun May  6 15:25:27 2018 selector starting...
Traceback (most recent call last):
  File "selector.py", line 73, in <module>
    sock.connect((config['crawler_config']['host'], config['crawler_config']['port']))
  File "/usr/lib/python2.7/socket.py", line 228, in meth
    return getattr(self._sock,name)(*args)
socket.error: [Errno 111] Connection refused
